<?xml version="1.0"?>
<sdf version="1.7">
    <model name="panda">

        <!-- Fix To World -->
        <joint name="panda_joint_world" type="fixed">
            <parent>world</parent>
            <child>panda_link0</child>
        </joint>


        <!-- Arm Links -->
        <link name="panda_link0">
            <visual name="panda_link0_visual">
                <geometry>
                    <mesh>
                        <uri>model://panda/meshes/visual/link0.dae</uri>
                    </mesh>
                </geometry>
            </visual>
            <collision name="panda_link0_collision">
                <geometry>
                    <mesh>
                        <uri>model://panda/meshes/collision/link0.stl</uri>
                    </mesh>
                </geometry>
                <surface>
                    <friction>
                        <ode>
                            <mu>1.05</mu>
                            <mu2>1.05</mu2>
                        </ode>
                    </friction>
                </surface>
            </collision>
            <inertial>
                <pose>-0.025566 -2.87883e-05 0.057332 0 0 0</pose>
                <mass>2.814271300104062</mass>
                <inertia>
                    <ixx>0.0075390636364814695</ixx>
                    <iyy>0.010508017427382959</iyy>
                    <izz>0.009864933638708275</izz>
                    <ixy>-1.5053124574783335e-05</ixy>
                    <ixz>-0.0012144328835738973</ixz>
                    <iyz>1.0434803501032979e-05</iyz>
                </inertia>
            </inertial>
        </link>

        <link name="panda_link1">
            <pose relative_to="panda_joint1">0 0 0 0 0 0</pose>
            <visual name="panda_link1_visual">
                <geometry>
                    <mesh>
                        <uri>model://panda/meshes/visual/link1.dae</uri>
                    </mesh>
                </geometry>
            </visual>
            <collision name="panda_link1_collision">
                <geometry>
                    <mesh>
                        <uri>model://panda/meshes/collision/link1.stl</uri>
                    </mesh>
                </geometry>
                <surface>
                    <friction>
                        <ode>
                            <mu>1.05</mu>
                            <mu2>1.05</mu2>
                        </ode>
                    </friction>
                </surface>
            </collision>
            <inertial>
                <pose>-3.72212e-09 -0.0324958 -0.0675818 0 0 0</pose>
                <mass>2.6433170427227215</mass>
                <inertia>
                    <ixx>0.017405076982879724</ixx>
                    <iyy>0.015352077935781732</iyy>
                    <izz>0.005987891663073857</izz>
                    <ixy>-8.687986369621078e-09</ixy>
                    <ixz>-1.6277819062920423e-08</ixz>
                    <iyz>0.004510855959102245</iyz>
                </inertia>
            </inertial>
        </link>

        <link name="panda_link2">
            <pose relative_to="panda_joint2">0 0 0 0 0 0</pose>
            <visual name="panda_link2_visual">
                <geometry>
                    <mesh>
                        <uri>model://panda/meshes/visual/link2.dae</uri>
                    </mesh>
                </geometry>
            </visual>
            <collision name="panda_link2_collision">
                <geometry>
                    <mesh>
                        <uri>model://panda/meshes/collision/link2.stl</uri>
                    </mesh>
                </geometry>
                <surface>
                    <friction>
                        <ode>
                            <mu>1.05</mu>
                            <mu2>1.05</mu2>
                        </ode>
                    </friction>
                </surface>
            </collision>
            <inertial>
                <pose>3.17833e-07 -0.06861 0.0322285 0 0 0</pose>
                <mass>2.6652755331661186</mass>
                <inertia>
                    <ixx>0.01778694005635383</ixx>
                    <iyy>0.006044133867952844</iyy>
                    <izz>0.01571095500455695</izz>
                    <ixy>8.70635625879119e-08</ixy>
                    <ixz>3.752072058394008e-08</ixz>
                    <iyz>-0.004599490295490376</iyz>
                </inertia>
            </inertial>
        </link>

        <link name="panda_link3">
            <pose relative_to="panda_joint3">0 0 0 0 0 0</pose>
            <visual name="panda_link3_visual">
                <geometry>
                    <mesh>
                        <uri>model://panda/meshes/visual/link3.dae</uri>
                    </mesh>
                </geometry>
            </visual>
            <collision name="panda_link3_collision">
                <geometry>
                    <mesh>
                        <uri>model://panda/meshes/collision/link3.stl</uri>
                    </mesh>
                </geometry>
                <surface>
                    <friction>
                        <ode>
                            <mu>1.05</mu>
                            <mu2>1.05</mu2>
                        </ode>
                    </friction>
                </surface>
            </collision>
            <inertial>
                <pose>0.0469893 0.0316374 -0.031704 0 0 0</pose>
                <mass>2.3293714829045733</mass>
                <inertia>
                    <ixx>0.0075496764161139766</ixx>
                    <iyy>0.009680676080191398</iyy>
                    <izz>0.007944557422008086</izz>
                    <ixy>-0.0024320464513492225</ixy>
                    <ixz>-0.003250815048103007</ixz>
                    <iyz>-0.0021316282421730694</iyz>
                </inertia>
            </inertial>
        </link>

        <link name="panda_link4">
            <pose relative_to="panda_joint4">0 0 0 0 0 0</pose>
            <visual name="panda_link4_visual">
                <geometry>
                    <mesh>
                        <uri>model://panda/meshes/visual/link4.dae</uri>
                    </mesh>
                </geometry>
            </visual>
            <collision name="panda_link4_collision">
                <geometry>
                    <mesh>
                        <uri>model://panda/meshes/collision/link4.stl</uri>
                    </mesh>
                </geometry>
                <surface>
                    <friction>
                        <ode>
                            <mu>1.05</mu>
                            <mu2>1.05</mu2>
                        </ode>
                    </friction>
                </surface>
            </collision>
            <inertial>
                <pose>-0.0360505 0.0337069 0.0319019 0 0 0</pose>
                <mass>2.3104763646281508</mass>
                <inertia>
                    <ixx>0.007764568814864828</ixx>
                    <iyy>0.008015776929980149</iyy>
                    <izz>0.009955882308071066</izz>
                    <ixy>0.003371475204045935</ixy>
                    <ixz>-0.002343621113168248</ixz>
                    <iyz>0.0022917526161470624</iyz>
                </inertia>
            </inertial>
        </link>

        <link name="panda_link5">
            <pose relative_to="panda_joint5">0 0 0 0 0 0</pose>
            <visual name="panda_link5_visual">
                <geometry>
                    <mesh>
                        <uri>model://panda/meshes/visual/link5.dae</uri>
                    </mesh>
                </geometry>
            </visual>
            <collision name="panda_link5_collision">
                <geometry>
                    <mesh>
                        <uri>model://panda/meshes/collision/link5.stl</uri>
                    </mesh>
                </geometry>
                <surface>
                    <friction>
                        <ode>
                            <mu>1.05</mu>
                            <mu2>1.05</mu2>
                        </ode>
                    </friction>
                </surface>
            </collision>
            <inertial>
                <pose>-6.12525e-06 0.0610427 -0.104176 0 0 0</pose>
                <mass>2.6226426154892004</mass>
                <inertia>
                    <ixx>0.029070538014399377</ixx>
                    <iyy>0.027638529986528795</iyy>
                    <izz>0.004251111234400737</izz>
                    <ixy>6.208738268725568e-07</ixy>
                    <ixz>-1.0059151925023392e-05</ixz>
                    <iyz>-0.007424306477850814</iyz>
                </inertia>
            </inertial>
        </link>

        <link name="panda_link6">
            <pose relative_to="panda_joint6">0 0 0 0 0 0</pose>
            <visual name="panda_link6_visual">
                <geometry>
                    <mesh>
                        <uri>model://panda/meshes/visual/link6.dae</uri>
                    </mesh>
                </geometry>
            </visual>
            <collision name="panda_link6_collision">
                <geometry>
                    <mesh>
                        <uri>model://panda/meshes/collision/link6.stl</uri>
                    </mesh>
                </geometry>
                <surface>
                    <friction>
                        <ode>
                            <mu>1.05</mu>
                            <mu2>1.05</mu2>
                        </ode>
                    </friction>
                </surface>
            </collision>
            <inertial>
                <pose>0.051051 0.00910797 0.0106343 0 0 0</pose>
                <mass>1.5025804886626795</mass>
                <inertia>
                    <ixx>0.002940555801469018</ixx>
                    <iyy>0.00392105201248677</iyy>
                    <izz>0.0054115603870960195</izz>
                    <ixy>-0.00042391108351381507</ixy>
                    <ixz>0.000610007735338717</ixz>
                    <iyz>0.00012647545430836214</iyz>
                </inertia>
            </inertial>
        </link>

        <link name="panda_link7">
            <pose relative_to="panda_joint7">0 0 0 0 0 0</pose>
            <visual name="panda_link7_visual">
                <geometry>
                    <mesh>
                        <uri>model://panda/meshes/visual/link7.dae</uri>
                    </mesh>
                </geometry>
            </visual>
            <collision name="panda_link7_collision">
                <geometry>
                    <mesh>
                        <uri>model://panda/meshes/collision/link7.stl</uri>
                    </mesh>
                </geometry>
                <surface>
                    <friction>
                        <ode>
                            <mu>1.05</mu>
                            <mu2>1.05</mu2>
                        </ode>
                    </friction>
                </surface>
            </collision>
            <inertial>
                <pose>0.0109695 0.0107965 0.0650412 0 0 0</pose>
                <mass>0.5237668134788256</mass>
                <inertia>
                    <ixx>0.0008621467959726535</ixx>
                    <iyy>0.0008613100184801048</iyy>
                    <izz>0.0006961139396618219</izz>
                    <ixy>-0.00011871071570425467</ixy>
                    <ixz>3.866602604509339e-05</ixz>
                    <iyz>-9.057841649422724e-05</iyz>
                </inertia>
            </inertial>
        </link>


        <!-- Arm Joints -->
        <joint name="panda_joint1" type="revolute">
            <pose relative_to="panda_link0">0 0 0.333 0 0 0</pose>
            <parent>panda_link0</parent>
            <child>panda_link1</child>
            <axis>
                <xyz>0 0 1</xyz>
                <limit>
                    <effort>87</effort>
                    <lower>-2.897246558310587</lower>
                    <upper>2.897246558310587</upper>
                    <velocity>2.617993877991494</velocity>
                </limit>
                <dynamics>
                    <spring_reference>0</spring_reference>
                    <spring_stiffness>0</spring_stiffness>
                    <damping>21.75</damping>
                    <friction>3.48</friction>
                </dynamics>
            </axis>
        </joint>

        <joint name="panda_joint2" type="revolute">
            <pose relative_to="panda_link1">0 0 0 -1.570796326794897 0 0</pose>
            <parent>panda_link1</parent>
            <child>panda_link2</child>
            <axis>
                <xyz>0 0 1</xyz>
                <limit>
                    <effort>87</effort>
                    <lower>-1.762782544514273</lower>
                    <upper>1.762782544514273</upper>
                    <velocity>2.617993877991494</velocity>
                </limit>
                <dynamics>
                    <spring_reference>0</spring_reference>
                    <spring_stiffness>0</spring_stiffness>
                    <damping>21.75</damping>
                    <friction>3.48</friction>
                </dynamics>
            </axis>
        </joint>

        <joint name="panda_joint3" type="revolute">
            <pose relative_to="panda_link2">0 -0.316 0 1.570796326794897 0 0</pose>
            <parent>panda_link2</parent>
            <child>panda_link3</child>
            <axis>
                <xyz>0 0 1</xyz>
                <limit>
                    <effort>87</effort>
                    <lower>-2.897246558310587</lower>
                    <upper>2.897246558310587</upper>
                    <velocity>2.617993877991494</velocity>
                </limit>
                <dynamics>
                    <spring_reference>0</spring_reference>
                    <spring_stiffness>0</spring_stiffness>
                    <damping>21.75</damping>
                    <friction>3.48</friction>
                </dynamics>
            </axis>
        </joint>

        <joint name="panda_joint4" type="revolute">
            <pose relative_to="panda_link3">0.0825 0 0 1.570796326794897 0 0</pose>
            <parent>panda_link3</parent>
            <child>panda_link4</child>
            <axis>
                <xyz>0 0 1</xyz>
                <limit>
                    <effort>87</effort>
                    <lower>-3.07177948351002</lower>
                    <upper>-0.06981317007977318</upper>
                    <velocity>2.617993877991494</velocity>
                </limit>
                <dynamics>
                    <spring_reference>0</spring_reference>
                    <spring_stiffness>0</spring_stiffness>
                    <damping>21.75</damping>
                    <friction>3.48</friction>
                </dynamics>
            </axis>
        </joint>

        <joint name="panda_joint5" type="revolute">
            <pose relative_to="panda_link4">-0.0825 0.384 0 -1.570796326794897 0 0</pose>
            <parent>panda_link4</parent>
            <child>panda_link5</child>
            <axis>
                <xyz>0 0 1</xyz>
                <limit>
                    <effort>12</effort>
                    <lower>-2.897246558310587</lower>
                    <upper>2.897246558310587</upper>
                    <velocity>3.141592653589793</velocity>
                </limit>
                <dynamics>
                    <spring_reference>0</spring_reference>
                    <spring_stiffness>0</spring_stiffness>
                    <damping>3.0</damping>
                    <friction>0.48</friction>
                </dynamics>
            </axis>
        </joint>

        <joint name="panda_joint6" type="revolute">
            <pose relative_to="panda_link5">0 0 0 1.570796326794897 0 0</pose>
            <parent>panda_link5</parent>
            <child>panda_link6</child>
            <axis>
                <xyz>0 0 1</xyz>
                <limit>
                    <effort>12</effort>
                    <lower>-0.0174532925199433</lower>
                    <upper>3.752457891787809</upper>
                    <velocity>3.141592653589793</velocity>
                </limit>
                <dynamics>
                    <spring_reference>0</spring_reference>
                    <spring_stiffness>0</spring_stiffness>
                    <damping>3.0</damping>
                    <friction>0.48</friction>
                </dynamics>
            </axis>
        </joint>

        <joint name="panda_joint7" type="revolute">
            <pose relative_to="panda_link6">0.088 0 0 1.570796326794897 0 0</pose>
            <parent>panda_link6</parent>
            <child>panda_link7</child>
            <axis>
                <xyz>0 0 1</xyz>
                <limit>
                    <effort>12</effort>
                    <lower>-2.897246558310587</lower>
                    <upper>2.897246558310587</upper>
                    <velocity>3.141592653589793</velocity>
                </limit>
                <dynamics>
                    <spring_reference>0</spring_reference>
                    <spring_stiffness>0</spring_stiffness>
                    <damping>3.0</damping>
                    <friction>0.48</friction>
                </dynamics>
            </axis>
        </joint>


        <!-- Arm-Hand Fixed Joint -->
        <joint name="panda_hand_joint" type="fixed">
            <pose relative_to="panda_link7">0 0 0.107 0 0 -0.7853981633974483</pose>
            <parent>panda_link7</parent>
            <child>panda_hand</child>
        </joint>


        <!-- Hand Links -->
        <link name="panda_hand">
            <pose relative_to="panda_hand_joint">0 0 0 0 0 0</pose>
            <visual name="panda_hand_visual">
                <pose>0 0 0 0 0 0</pose>
                <geometry>
                    <mesh>
                        <uri>model://panda/meshes/visual/hand.dae</uri>
                    </mesh>
                </geometry>
            </visual>
            <collision name="panda_hand_collision">
                <pose>0 0 0 0 0 0</pose>
                <geometry>
                    <mesh>
                        <uri>model://panda/meshes/collision/hand.stl</uri>
                    </mesh>
                </geometry>
                <surface>
                    <friction>
                        <ode>
                            <mu>1.05</mu>
                            <mu2>1.05</mu2>
                        </ode>
                    </friction>
                </surface>
            </collision>
            <inertial>
                <pose>-6.7624e-06 0.00152435 0.0275912 0 0 0</pose>
                <mass>0.14060765127978503</mass>
                <inertia>
                    <ixx>0.0005365450414352072</ixx>
                    <iyy>7.70511954783727e-05</iyy>
                    <izz>0.0004938176882694914</izz>
                    <ixy>1.7911952957732454e-08</ixy>
                    <ixz>-2.320071910601251e-08</ixz>
                    <iyz>4.681149945315967e-08</iyz>
                </inertia>
            </inertial>
        </link>

        <link name="panda_leftfinger">
            <pose relative_to="panda_finger_joint1">0 0 0 0 0 0</pose>
            <visual name="panda_leftfinger_visual">
                <geometry>
                    <mesh>
                        <uri>model://panda/meshes/visual/finger.dae</uri>
                    </mesh>
                </geometry>
            </visual>
            <collision name="panda_leftfinger_collision">
                <geometry>
                    <mesh>
                        <uri>model://panda/meshes/collision/finger.stl</uri>
                    </mesh>
                </geometry>
                <surface>
                    <friction>
                        <ode>
                            <mu>2.15</mu>
                            <mu2>2.15</mu2>
                        </ode>
                    </friction>
                </surface>
            </collision>
            <inertial>
                <pose>-6.2561e-06 0.00227781 -0.0277116 0 0 0</pose>
                <mass>0.2238453537819424</mass>
                <inertia>
                    <ixx>6.74804167363695e-05</ixx>
                    <iyy>6.627189221641395e-05</iyy>
                    <izz>1.550396267804825e-05</izz>
                    <ixy>-4.1027443646025676e-09</ixy>
                    <ixz>1.8693673970152995e-08</ixz>
                    <iyz>1.1967548474390802e-05</iyz>
                </inertia>
            </inertial>
        </link>

        <link name="panda_rightfinger">
            <pose relative_to="panda_finger_joint2">0 0 0 0 0 0</pose>
            <visual name="panda_rightfinger_visual">
                <pose>0 0 0 0 0 3.141592653589793</pose>
                <geometry>
                    <mesh>
                        <uri>model://panda/meshes/visual/finger.dae</uri>
                    </mesh>
                </geometry>
            </visual>
            <collision name="panda_rightfinger_collision">
                <pose>0 0 0 0 0 3.141592653589793</pose>
                <geometry>
                    <mesh>
                        <uri>model://panda/meshes/collision/finger.stl</uri>
                    </mesh>
                </geometry>
                <surface>
                    <friction>
                        <ode>
                            <mu>2.15</mu>
                            <mu2>2.15</mu2>
                        </ode>
                    </friction>
                </surface>
            </collision>
            <inertial>
                <pose>-6.2561e-06 0.00227781 -0.0277116 0 0 3.141592653589793</pose>
                <mass>0.2238453537819424</mass>
                <inertia>
                    <ixx>6.74804167363695e-05</ixx>
                    <iyy>6.627189221641395e-05</iyy>
                    <izz>1.550396267804825e-05</izz>
                    <ixy>-4.1027443646025676e-09</ixy>
                    <ixz>1.8693673970152995e-08</ixz>
                    <iyz>1.1967548474390802e-05</iyz>
                </inertia>
            </inertial>
        </link>


        <!-- Finger Joints -->
        <joint name="panda_finger_joint1" type="prismatic">
            <pose relative_to="panda_hand">0 0 0.0584 0 0 0</pose>
            <parent>panda_hand</parent>
            <child>panda_leftfinger</child>
            <axis>
                <xyz>0 1 0</xyz>
                <limit>
                    <effort>20</effort>
                    <lower>0.0</lower>
                    <upper>0.04</upper>
                    <velocity>0.2</velocity>
                </limit>
                <dynamics>
                    <spring_reference>0</spring_reference>
                    <spring_stiffness>0</spring_stiffness>
                    <damping>10</damping>
                    <friction>0.5</friction>
                </dynamics>
            </axis>
        </joint>

        <joint name="panda_finger_joint2" type="prismatic">
            <pose relative_to="panda_hand">0 0 0.0584 0 0 0</pose>
            <parent>panda_hand</parent>
            <child>panda_rightfinger</child>
            <axis>
                <xyz>0 -1 0</xyz>
                <limit>
                    <effort>20</effort>
                    <lower>0.0</lower>
                    <upper>0.04</upper>
                    <velocity>0.2</velocity>
                </limit>
                <dynamics>
                    <spring_reference>0</spring_reference>
                    <spring_stiffness>0</spring_stiffness>
                    <damping>10</damping>
                    <friction>0.5</friction>
                </dynamics>
            </axis>
        </joint>


        <!-- End-effector -->
        <link name="panda_link8">
            <pose relative_to="end_effector_frame_fixed_joint">0 0 0 0 0 0</pose>
        </link>
        <joint name="end_effector_frame_fixed_joint" type="fixed">
            <pose relative_to="panda_hand">0 0 0.103 0 0 0</pose>
            <parent>panda_hand</parent>
            <child>panda_link8</child>
        </joint>

    </model>
</sdf>
