<?xml version="1.0"?>
<robot name="panda">

    <!-- Arm Links -->
    <link name="panda_link0">
        <visual>
            <geometry>
                <mesh filename="package://panda_ign/meshes/visual/link0.dae" />
            </geometry>
        </visual>
        <collision>
            <geometry>
                <mesh filename="package://panda_ign/meshes/collision/link0.stl" />
            </geometry>
        </collision>
    </link>

    <link name="panda_link1">
        <visual>
            <geometry>
                <mesh filename="package://panda_ign/meshes/visual/link1.dae" />
            </geometry>
        </visual>
        <collision>
            <geometry>
                <mesh filename="package://panda_ign/meshes/collision/link1.stl" />
            </geometry>
        </collision>
    </link>

    <link name="panda_link2">
        <visual>
            <geometry>
                <mesh filename="package://panda_ign/meshes/visual/link2.dae" />
            </geometry>
        </visual>
        <collision>
            <geometry>
                <mesh filename="package://panda_ign/meshes/collision/link2.stl" />
            </geometry>
        </collision>
    </link>

    <link name="panda_link3">
        <visual>
            <geometry>
                <mesh filename="package://panda_ign/meshes/visual/link3.dae" />
            </geometry>
        </visual>
        <collision>
            <geometry>
                <mesh filename="package://panda_ign/meshes/collision/link3.stl" />
            </geometry>
        </collision>
    </link>

    <link name="panda_link4">
        <visual>
            <geometry>
                <mesh filename="package://panda_ign/meshes/visual/link4.dae" />
            </geometry>
        </visual>
        <collision>
            <geometry>
                <mesh filename="package://panda_ign/meshes/collision/link4.stl" />
            </geometry>
        </collision>
    </link>

    <link name="panda_link5">
        <visual>
            <geometry>
                <mesh filename="package://panda_ign/meshes/visual/link5.dae" />
            </geometry>
        </visual>
        <collision>
            <geometry>
                <mesh filename="package://panda_ign/meshes/collision/link5.stl" />
            </geometry>
        </collision>
    </link>

    <link name="panda_link6">
        <visual>
            <geometry>
                <mesh filename="package://panda_ign/meshes/visual/link6.dae" />
            </geometry>
        </visual>
        <collision>
            <geometry>
                <mesh filename="package://panda_ign/meshes/collision/link6.stl" />
            </geometry>
        </collision>
    </link>

    <link name="panda_link7">
        <visual>
            <geometry>
                <mesh filename="package://panda_ign/meshes/visual/link7.dae" />
            </geometry>
        </visual>
        <collision>
            <geometry>
                <mesh filename="package://panda_ign/meshes/collision/link7.stl" />
            </geometry>
        </collision>
    </link>


    <!-- Arm Joints -->
    <joint name="panda_joint1" type="revolute">
        <parent link="panda_link0" />
        <child link="panda_link1" />
        <origin rpy="0 0 0" xyz="0 0 0.333" />
        <axis xyz="0 0 1" />
        <limit effort="87" lower="-2.897246558310587" upper="2.897246558310587" velocity="2.617993877991494"/>
    </joint>

    <joint name="panda_joint2" type="revolute">
        <parent link="panda_link1" />
        <child link="panda_link2" />
        <origin rpy="-1.570796326794897 0 0" xyz="0 0 0" />
        <axis xyz="0 0 1" />
        <limit effort="87" lower="-1.762782544514273" upper="1.762782544514273" velocity="2.617993877991494"/>
    </joint>

    <joint name="panda_joint3" type="revolute">
        <parent link="panda_link2" />
        <child link="panda_link3" />
        <origin rpy="1.570796326794897 0 0" xyz="0 -0.316 0" />
        <axis xyz="0 0 1" />
        <limit effort="87" lower="-2.897246558310587" upper="2.897246558310587" velocity="2.617993877991494"/>
    </joint>

    <joint name="panda_joint4" type="revolute">
        <parent link="panda_link3" />
        <child link="panda_link4" />
        <origin rpy="1.570796326794897 0 0" xyz="0.0825 0 0" />
        <axis xyz="0 0 1" />
        <limit effort="87" lower="-3.07177948351002" upper="-0.06981317007977318" velocity="2.617993877991494"/>
    </joint>

    <joint name="panda_joint5" type="revolute">
        <parent link="panda_link4" />
        <child link="panda_link5" />
        <origin rpy="-1.570796326794897 0 0" xyz="-0.0825 0.384 0" />
        <axis xyz="0 0 1" />
        <limit effort="12" lower="-2.897246558310587" upper="2.897246558310587" velocity="3.141592653589793"/>
    </joint>

    <joint name="panda_joint6" type="revolute">
        <parent link="panda_link5" />
        <child link="panda_link6" />
        <origin rpy="1.570796326794897 0 0" xyz="0 0 0" />
        <axis xyz="0 0 1" />
        <limit effort="12" lower="-0.0174532925199433" upper="3.752457891787809" velocity="3.141592653589793"/>
    </joint>

    <joint name="panda_joint7" type="revolute">
        <parent link="panda_link6" />
        <child link="panda_link7" />
        <origin rpy="1.570796326794897 0 0" xyz="0.088 0 0" />
        <axis xyz="0 0 1" />
        <limit effort="12" lower="-2.897246558310587" upper="2.897246558310587" velocity="3.141592653589793"/>
    </joint>


    <!-- Arm-Hand Fixed Joint -->
    <joint name="panda_hand_joint" type="fixed">
        <parent link="panda_link7" />
        <child link="panda_hand" />
        <origin rpy="0 0 -0.7853981633974483" xyz="0 0 0.107" />
    </joint>


    <!-- Hand Links -->
    <link name="panda_hand">
        <visual>
            <geometry>
                <mesh filename="package://panda_ign/meshes/visual/hand.dae" />
            </geometry>
        </visual>
        <collision>
            <geometry>
                <mesh filename="package://panda_ign/meshes/collision/hand.stl" />
            </geometry>
        </collision>
    </link>

    <link name="panda_leftfinger">
        <visual>
            <geometry>
                <mesh filename="package://panda_ign/meshes/visual/finger.dae" />
            </geometry>
        </visual>
        <collision>
            <geometry>
                <mesh filename="package://panda_ign/meshes/collision/finger.stl" />
            </geometry>
        </collision>
    </link>

    <link name="panda_rightfinger">
        <visual>
            <origin rpy="0 0 3.141592653589793" xyz="0 0 0" />
            <geometry>
                <mesh filename="package://panda_ign/meshes/visual/finger.dae" />
            </geometry>
        </visual>
        <collision>
            <origin rpy="0 0 3.141592653589793" xyz="0 0 0" />
            <geometry>
                <mesh filename="package://panda_ign/meshes/collision/finger.stl" />
            </geometry>
        </collision>
    </link>


    <!-- Finger Joints -->
    <joint name="panda_finger_joint1" type="prismatic">
        <parent link="panda_hand" />
        <child link="panda_leftfinger" />
        <origin rpy="0 0 0" xyz="0 0 0.0584" />
        <axis xyz="0 1 0" />
        <limit effort="20" lower="0.0" upper="0.04" velocity="0.2" />
    </joint>

    <joint name="panda_finger_joint2" type="prismatic">
        <parent link="panda_hand" />
        <child link="panda_rightfinger" />
        <origin rpy="0 0 0" xyz="0 0 0.0584" />
        <axis xyz="0 -1 0" />
        <limit effort="20" lower="0.0" upper="0.04" velocity="0.2" />
        <mimic joint="panda_finger_joint1" />
    </joint>


    <!-- End-effector -->
    <link name="panda_link8" />
    <joint name="end_effector_frame_fixed_joint" type="fixed">
        <parent link="panda_hand"/>
        <child link="panda_link8"/>
        <origin rpy="0 0 0" xyz="0 0 0.103"/>
    </joint>

</robot>
