<?xml version="1.0"?>
<robot name="panda">

    <!-- Arm Links -->
    <link name="panda_link0">
        <visual>
            <geometry>
                <mesh filename="package://panda_ign/meshes/visual/link0.dae" />
            </geometry>
        </visual>
        <collision>
            <geometry>
                <mesh filename="package://panda_ign/meshes/collision/link0.stl" />
            </geometry>
        </collision>
        <inertial>
            <origin rpy="0 0 0" xyz="-0.025566 -2.88e-05 0.057332"/>
            <mass value="2.92"/>
            <inertia ixx="0.00782229414331" ixy="-1.56191622996e-05" ixz="-0.00126005738123" iyy="0.0109027971813" iyz="1.08233858202e-05" izz="0.0102355503949"/>
        </inertial>
    </link>

    <link name="panda_link1">
        <visual>
            <geometry>
                <mesh filename="package://panda_ign/meshes/visual/link1.dae" />
            </geometry>
        </visual>
        <collision>
            <geometry>
                <mesh filename="package://panda_ign/meshes/collision/link1.stl" />
            </geometry>
        </collision>
        <inertial>
            <origin rpy="0 0 0" xyz="0 -0.0324958 -0.0675818"/>
            <mass value="2.74"/>
            <inertia ixx="0.0180416958283" ixy="0.0" ixz="0.0" iyy="0.0159136071891" iyz="0.0046758424612" izz="0.00620690827127"/>
        </inertial>
    </link>

    <link name="panda_link2">
        <visual>
            <geometry>
                <mesh filename="package://panda_ign/meshes/visual/link2.dae" />
            </geometry>
        </visual>
        <collision>
            <geometry>
                <mesh filename="package://panda_ign/meshes/collision/link2.stl" />
            </geometry>
        </collision>
        <inertial>
            <origin rpy="0 0 0" xyz="0 -0.06861 0.0322285"/>
            <mass value="2.74"/>
            <inertia ixx="0.0182856182281" ixy="0.0" ixz="0.0" iyy="0.00621358421175" iyz="-0.00472844221905" izz="0.0161514346309"/>
        </inertial>
    </link>

    <link name="panda_link3">
        <visual>
            <geometry>
                <mesh filename="package://panda_ign/meshes/visual/link3.dae" />
            </geometry>
        </visual>
        <collision>
            <geometry>
                <mesh filename="package://panda_ign/meshes/collision/link3.stl" />
            </geometry>
        </collision>
        <inertial>
            <origin rpy="0 0 0" xyz="0.0469893 0.0316374 -0.031704"/>
            <mass value="2.38"/>
            <inertia ixx="0.00771376630908" ixy="-0.00248490625138" ixz="-0.00332147581033" iyy="0.00989108008727" iyz="-0.00217796151484" izz="0.00811723558464"/>
        </inertial>
    </link>

    <link name="panda_link4">
        <visual>
            <geometry>
                <mesh filename="package://panda_ign/meshes/visual/link4.dae" />
            </geometry>
        </visual>
        <collision>
            <geometry>
                <mesh filename="package://panda_ign/meshes/collision/link4.stl" />
            </geometry>
        </collision>
        <inertial>
            <origin rpy="0 0 0" xyz="-0.0360446 0.0336853 0.031882"/>
            <mass value="2.38"/>
            <inertia ixx="0.00799663881132" ixy="0.00347095570217" ixz="-0.00241222942995" iyy="0.00825390705278" iyz="0.00235774044121" izz="0.0102515004345"/>
        </inertial>
    </link>

    <link name="panda_link5">
        <visual>
            <geometry>
                <mesh filename="package://panda_ign/meshes/visual/link5.dae" />
            </geometry>
        </visual>
        <collision>
            <geometry>
                <mesh filename="package://panda_ign/meshes/collision/link5.stl" />
            </geometry>
        </collision>
        <inertial>
            <origin rpy="0 0 0" xyz="0 0.0610427 -0.104176"/>
            <mass value="2.74"/>
            <inertia ixx="0.030371374513" ixy="6.50283587108e-07" ixz="-1.05129179916e-05" iyy="0.0288752887402" iyz="-0.00775653445787" izz="0.00444134056164"/>
        </inertial>
    </link>

    <link name="panda_link6">
        <visual>
            <geometry>
                <mesh filename="package://panda_ign/meshes/visual/link6.dae" />
            </geometry>
        </visual>
        <collision>
            <geometry>
                <mesh filename="package://panda_ign/meshes/collision/link6.stl" />
            </geometry>
        </collision>
        <inertial>
            <origin rpy="0 0 0" xyz="0.0510509 0.009108 0.0106343"/>
            <mass value="1.55"/>
            <inertia ixx="0.00303336450376" ixy="-0.000437276865508" ixz="0.000629257294877" iyy="0.00404479911567" iyz="0.000130472021025" izz="0.00558234286039"/>
        </inertial>
    </link>

    <link name="panda_link7">
        <visual>
            <geometry>
                <mesh filename="package://panda_ign/meshes/visual/link7.dae" />
            </geometry>
        </visual>
        <collision>
            <geometry>
                <mesh filename="package://panda_ign/meshes/collision/link7.stl" />
            </geometry>
        </collision>
        <inertial>
            <origin rpy="0 0 0" xyz="0.0109695 0.0107965 0.0650411"/>
            <mass value="0.54"/>
            <inertia ixx="0.000888868887021" ixy="-0.00012239074652" ixz="3.98699829666e-05" iyy="0.000888001373233" iyz="-9.33825115206e-05" izz="0.0007176834609"/>
        </inertial>
    </link>


    <!-- Arm Joints -->
    <joint name="panda_joint1" type="revolute">
        <parent link="panda_link0" />
        <child link="panda_link1" />
        <origin rpy="0 0 0" xyz="0 0 0.333" />
        <axis xyz="0 0 1" />
        <limit effort="87" lower="-2.897246558310587" upper="2.897246558310587" velocity="2.617993877991494"/>
    </joint>

    <joint name="panda_joint2" type="revolute">
        <parent link="panda_link1" />
        <child link="panda_link2" />
        <origin rpy="-1.570796326794897 0 0" xyz="0 0 0" />
        <axis xyz="0 0 1" />
        <limit effort="87" lower="-1.762782544514273" upper="1.762782544514273" velocity="2.617993877991494"/>
    </joint>

    <joint name="panda_joint3" type="revolute">
        <parent link="panda_link2" />
        <child link="panda_link3" />
        <origin rpy="1.570796326794897 0 0" xyz="0 -0.316 0" />
        <axis xyz="0 0 1" />
        <limit effort="87" lower="-2.897246558310587" upper="2.897246558310587" velocity="2.617993877991494"/>
    </joint>

    <joint name="panda_joint4" type="revolute">
        <parent link="panda_link3" />
        <child link="panda_link4" />
        <origin rpy="1.570796326794897 0 0" xyz="0.0825 0 0" />
        <axis xyz="0 0 1" />
        <limit effort="87" lower="-3.07177948351002" upper="-0.06981317007977318" velocity="2.617993877991494"/>
    </joint>

    <joint name="panda_joint5" type="revolute">
        <parent link="panda_link4" />
        <child link="panda_link5" />
        <origin rpy="-1.570796326794897 0 0" xyz="-0.0825 0.384 0" />
        <axis xyz="0 0 1" />
        <limit effort="12" lower="-2.897246558310587" upper="2.897246558310587" velocity="3.141592653589793"/>
    </joint>

    <joint name="panda_joint6" type="revolute">
        <parent link="panda_link5" />
        <child link="panda_link6" />
        <origin rpy="1.570796326794897 0 0" xyz="0 0 0" />
        <axis xyz="0 0 1" />
        <limit effort="12" lower="-0.0174532925199433" upper="3.752457891787809" velocity="3.141592653589793"/>
    </joint>

    <joint name="panda_joint7" type="revolute">
        <parent link="panda_link6" />
        <child link="panda_link7" />
        <origin rpy="1.570796326794897 0 0" xyz="0.088 0 0" />
        <axis xyz="0 0 1" />
        <limit effort="12" lower="-2.897246558310587" upper="2.897246558310587" velocity="3.141592653589793"/>
    </joint>


    <!-- Arm-Hand Fixed Joint -->
    <joint name="panda_hand_joint" type="fixed">
        <parent link="panda_link7" />
        <child link="panda_hand" />
        <origin rpy="0 0 -0.7853981633974483" xyz="0 0 0.107" />
    </joint>


    <!-- Hand Links -->
    <link name="panda_hand">
        <visual>
            <geometry>
                <mesh filename="package://panda_ign/meshes/visual/hand.dae" />
            </geometry>
        </visual>
        <collision>
            <geometry>
                <mesh filename="package://panda_ign/meshes/collision/hand.stl" />
            </geometry>
        </collision>
        <inertial>
            <origin rpy="0 0 0" xyz="0 0.0015244 0.0275912"/>
            <mass value="0.73"/>
            <inertia ixx="0.00278560230025" ixy="0.0" ixz="0.0" iyy="0.000400033405336" iyz="0.0" izz="0.00256378041832"/>
        </inertial>
    </link>

    <link name="panda_leftfinger">
        <visual>
            <geometry>
                <mesh filename="package://panda_ign/meshes/visual/finger.dae" />
            </geometry>
        </visual>
        <collision>
            <geometry>
                <mesh filename="package://panda_ign/meshes/collision/finger.stl" />
            </geometry>
        </collision>
        <inertial>
            <origin rpy="0 0 0" xyz="0 0.0145644 0.0227941"/>
            <mass value="0.1"/>
            <inertia ixx="3.01220925051e-05" ixy="0.0" ixz="0.0" iyy="2.95873808038e-05" iyz="0.0" izz="6.95125211657e-06"/>
        </inertial>
    </link>

    <link name="panda_rightfinger">
        <visual>
            <origin rpy="0 0 3.141592653589793" xyz="0 0 0" />
            <geometry>
                <mesh filename="package://panda_ign/meshes/visual/finger.dae" />
            </geometry>
        </visual>
        <collision>
            <origin rpy="0 0 3.141592653589793" xyz="0 0 0" />
            <geometry>
                <mesh filename="package://panda_ign/meshes/collision/finger.stl" />
            </geometry>
        </collision>
        <inertial>
            <origin rpy="0 0 3.141592653589793" xyz="0 0.0145644 0.0227941"/>
            <mass value="0.1"/>
            <inertia ixx="3.01220925051e-05" ixy="0.0" ixz="0.0" iyy="2.95873808038e-05" iyz="0.0" izz="6.95125211657e-06"/>
        </inertial>
    </link>


    <!-- Finger Joints -->
    <joint name="panda_finger_joint1" type="prismatic">
        <parent link="panda_hand" />
        <child link="panda_leftfinger" />
        <origin rpy="0 0 0" xyz="0 0 0.0584" />
        <axis xyz="0 1 0" />
        <limit effort="20" lower="0.0" upper="0.04" velocity="0.2" />
    </joint>

    <joint name="panda_finger_joint2" type="prismatic">
        <parent link="panda_hand" />
        <child link="panda_rightfinger" />
        <origin rpy="0 0 0" xyz="0 0 0.0584" />
        <axis xyz="0 -1 0" />
        <limit effort="20" lower="0.0" upper="0.04" velocity="0.2" />
        <mimic joint="panda_finger_joint1" />
    </joint>


    <!-- End-effector -->
    <link name="panda_link8" />
    <joint name="end_effector_frame_fixed_joint" type="fixed">
        <parent link="panda_hand"/>
        <child link="panda_link8"/>
        <origin rpy="0 0 0" xyz="0 0 0.103"/>
    </joint>

</robot>
